2022-03-12 22:50:50,612 ERROR: Exception on /user/gang [GET] [in c:\users\16496\appdata\local\programs\python\python37-32\lib\site-packages\flask\app.py:1458]
Traceback (most recent call last):
  File "c:\users\16496\appdata\local\programs\python\python37-32\lib\site-packages\flask\app.py", line 2073, in wsgi_app
    response = self.full_dispatch_request()
  File "c:\users\16496\appdata\local\programs\python\python37-32\lib\site-packages\flask\app.py", line 1518, in full_dispatch_request
    rv = self.handle_user_exception(e)
  File "c:\users\16496\appdata\local\programs\python\python37-32\lib\site-packages\flask\app.py", line 1516, in full_dispatch_request
    rv = self.dispatch_request()
  File "c:\users\16496\appdata\local\programs\python\python37-32\lib\site-packages\flask\app.py", line 1502, in dispatch_request
    return self.ensure_sync(self.view_functions[rule.endpoint])(**req.view_args)
  File "c:\users\16496\appdata\local\programs\python\python37-32\lib\site-packages\flask_login\utils.py", line 272, in decorated_view
    return func(*args, **kwargs)
  File "D:\python\microblog\app\routes.py", line 112, in user
    return render_template('user.html', user=user, posts=posts)
  File "c:\users\16496\appdata\local\programs\python\python37-32\lib\site-packages\flask\templating.py", line 150, in render_template
    ctx.app,
  File "c:\users\16496\appdata\local\programs\python\python37-32\lib\site-packages\flask\templating.py", line 128, in _render
    rv = template.render(context)
  File "c:\users\16496\appdata\local\programs\python\python37-32\lib\site-packages\jinja2\environment.py", line 1291, in render
    self.environment.handle_exception()
  File "c:\users\16496\appdata\local\programs\python\python37-32\lib\site-packages\jinja2\environment.py", line 925, in handle_exception
    raise rewrite_traceback_stack(source=source)
  File "D:\python\microblog\app\templates\user.html", line 1, in top-level template code
    {% extends "base.html" %}
  File "D:\python\microblog\app\templates\base.html", line 35, in top-level template code
    {% block content %}
  File "D:\python\microblog\app\templates\user.html", line 24, in block 'content'
    <a href="{{ url_for('follow', username=user.username) }}">¹Ø×¢</a>
  File "c:\users\16496\appdata\local\programs\python\python37-32\lib\site-packages\flask\helpers.py", line 338, in url_for
    return appctx.app.handle_url_build_error(error, endpoint, values)
  File "c:\users\16496\appdata\local\programs\python\python37-32\lib\site-packages\flask\helpers.py", line 326, in url_for
    endpoint, values, method=method, force_external=external
  File "c:\users\16496\appdata\local\programs\python\python37-32\lib\site-packages\werkzeug\routing.py", line 2315, in build
    raise BuildError(endpoint, values, method, self)
werkzeug.routing.BuildError: Could not build url for endpoint 'follow' with values ['username']. Did you mean 'login' instead?
2022-03-12 22:50:56,477 ERROR: Exception on /user/adan [GET] [in c:\users\16496\appdata\local\programs\python\python37-32\lib\site-packages\flask\app.py:1458]
Traceback (most recent call last):
  File "c:\users\16496\appdata\local\programs\python\python37-32\lib\site-packages\flask\app.py", line 2073, in wsgi_app
    response = self.full_dispatch_request()
  File "c:\users\16496\appdata\local\programs\python\python37-32\lib\site-packages\flask\app.py", line 1518, in full_dispatch_request
    rv = self.handle_user_exception(e)
  File "c:\users\16496\appdata\local\programs\python\python37-32\lib\site-packages\flask\app.py", line 1516, in full_dispatch_request
    rv = self.dispatch_request()
  File "c:\users\16496\appdata\local\programs\python\python37-32\lib\site-packages\flask\app.py", line 1502, in dispatch_request
    return self.ensure_sync(self.view_functions[rule.endpoint])(**req.view_args)
  File "c:\users\16496\appdata\local\programs\python\python37-32\lib\site-packages\flask_login\utils.py", line 272, in decorated_view
    return func(*args, **kwargs)
  File "D:\python\microblog\app\routes.py", line 112, in user
    return render_template('user.html', user=user, posts=posts)
  File "c:\users\16496\appdata\local\programs\python\python37-32\lib\site-packages\flask\templating.py", line 150, in render_template
    ctx.app,
  File "c:\users\16496\appdata\local\programs\python\python37-32\lib\site-packages\flask\templating.py", line 128, in _render
    rv = template.render(context)
  File "c:\users\16496\appdata\local\programs\python\python37-32\lib\site-packages\jinja2\environment.py", line 1291, in render
    self.environment.handle_exception()
  File "c:\users\16496\appdata\local\programs\python\python37-32\lib\site-packages\jinja2\environment.py", line 925, in handle_exception
    raise rewrite_traceback_stack(source=source)
  File "D:\python\microblog\app\templates\user.html", line 1, in top-level template code
    {% extends "base.html" %}
  File "D:\python\microblog\app\templates\base.html", line 35, in top-level template code
    {% block content %}
  File "D:\python\microblog\app\templates\user.html", line 24, in block 'content'
    <a href="{{ url_for('follow', username=user.username) }}">¹Ø×¢</a>
  File "c:\users\16496\appdata\local\programs\python\python37-32\lib\site-packages\flask\helpers.py", line 338, in url_for
    return appctx.app.handle_url_build_error(error, endpoint, values)
  File "c:\users\16496\appdata\local\programs\python\python37-32\lib\site-packages\flask\helpers.py", line 326, in url_for
    endpoint, values, method=method, force_external=external
  File "c:\users\16496\appdata\local\programs\python\python37-32\lib\site-packages\werkzeug\routing.py", line 2315, in build
    raise BuildError(endpoint, values, method, self)
werkzeug.routing.BuildError: Could not build url for endpoint 'follow' with values ['username']. Did you mean 'login' instead?
2022-03-12 22:52:05,113 ERROR: Exception on /user/adan [GET] [in c:\users\16496\appdata\local\programs\python\python37-32\lib\site-packages\flask\app.py:1458]
Traceback (most recent call last):
  File "c:\users\16496\appdata\local\programs\python\python37-32\lib\site-packages\flask\app.py", line 2073, in wsgi_app
    response = self.full_dispatch_request()
  File "c:\users\16496\appdata\local\programs\python\python37-32\lib\site-packages\flask\app.py", line 1518, in full_dispatch_request
    rv = self.handle_user_exception(e)
  File "c:\users\16496\appdata\local\programs\python\python37-32\lib\site-packages\flask\app.py", line 1516, in full_dispatch_request
    rv = self.dispatch_request()
  File "c:\users\16496\appdata\local\programs\python\python37-32\lib\site-packages\flask\app.py", line 1502, in dispatch_request
    return self.ensure_sync(self.view_functions[rule.endpoint])(**req.view_args)
  File "c:\users\16496\appdata\local\programs\python\python37-32\lib\site-packages\flask_login\utils.py", line 272, in decorated_view
    return func(*args, **kwargs)
  File "D:\python\microblog\app\routes.py", line 112, in user
    return render_template('user.html', user=user, posts=posts)
  File "c:\users\16496\appdata\local\programs\python\python37-32\lib\site-packages\flask\templating.py", line 150, in render_template
    ctx.app,
  File "c:\users\16496\appdata\local\programs\python\python37-32\lib\site-packages\flask\templating.py", line 128, in _render
    rv = template.render(context)
  File "c:\users\16496\appdata\local\programs\python\python37-32\lib\site-packages\jinja2\environment.py", line 1291, in render
    self.environment.handle_exception()
  File "c:\users\16496\appdata\local\programs\python\python37-32\lib\site-packages\jinja2\environment.py", line 925, in handle_exception
    raise rewrite_traceback_stack(source=source)
  File "D:\python\microblog\app\templates\user.html", line 1, in top-level template code
    {% extends "base.html" %}
  File "D:\python\microblog\app\templates\base.html", line 35, in top-level template code
    {% block content %}
  File "D:\python\microblog\app\templates\user.html", line 24, in block 'content'
    <a href="{{ url_for('follow', username=user.username) }}">¹Ø×¢</a>
  File "c:\users\16496\appdata\local\programs\python\python37-32\lib\site-packages\flask\helpers.py", line 338, in url_for
    return appctx.app.handle_url_build_error(error, endpoint, values)
  File "c:\users\16496\appdata\local\programs\python\python37-32\lib\site-packages\flask\helpers.py", line 326, in url_for
    endpoint, values, method=method, force_external=external
  File "c:\users\16496\appdata\local\programs\python\python37-32\lib\site-packages\werkzeug\routing.py", line 2315, in build
    raise BuildError(endpoint, values, method, self)
werkzeug.routing.BuildError: Could not build url for endpoint 'follow' with values ['username']. Did you mean 'login' instead?
2022-03-12 23:05:00,579 INFO: Microblog startup [in D:\python\microblog\app\__init__.py:44]
