2022-03-12 23:12:50,143 ERROR: Exception on /user/xiang [GET] [in c:\users\16496\appdata\local\programs\python\python37-32\lib\site-packages\flask\app.py:1458]
Traceback (most recent call last):
  File "c:\users\16496\appdata\local\programs\python\python37-32\lib\site-packages\flask\app.py", line 2073, in wsgi_app
    response = self.full_dispatch_request()
  File "c:\users\16496\appdata\local\programs\python\python37-32\lib\site-packages\flask\app.py", line 1518, in full_dispatch_request
    rv = self.handle_user_exception(e)
  File "c:\users\16496\appdata\local\programs\python\python37-32\lib\site-packages\flask\app.py", line 1516, in full_dispatch_request
    rv = self.dispatch_request()
  File "c:\users\16496\appdata\local\programs\python\python37-32\lib\site-packages\flask\app.py", line 1502, in dispatch_request
    return self.ensure_sync(self.view_functions[rule.endpoint])(**req.view_args)
  File "c:\users\16496\appdata\local\programs\python\python37-32\lib\site-packages\flask_login\utils.py", line 272, in decorated_view
    return func(*args, **kwargs)
  File "D:\python\microblog\app\routes.py", line 122, in user
    return render_template('user.html', user=user, posts=posts.items, next_url=next_url, prev_url=prev_url)
  File "c:\users\16496\appdata\local\programs\python\python37-32\lib\site-packages\flask\templating.py", line 150, in render_template
    ctx.app,
  File "c:\users\16496\appdata\local\programs\python\python37-32\lib\site-packages\flask\templating.py", line 128, in _render
    rv = template.render(context)
  File "c:\users\16496\appdata\local\programs\python\python37-32\lib\site-packages\jinja2\environment.py", line 1291, in render
    self.environment.handle_exception()
  File "c:\users\16496\appdata\local\programs\python\python37-32\lib\site-packages\jinja2\environment.py", line 925, in handle_exception
    raise rewrite_traceback_stack(source=source)
  File "D:\python\microblog\app\templates\user.html", line 1, in top-level template code
    {% extends "base.html" %}
  File "D:\python\microblog\app\templates\base.html", line 35, in top-level template code
    {% block content %}
  File "D:\python\microblog\app\templates\user.html", line 24, in block 'content'
    <a href="{{ url_for('follow', username=user.username) }}">¹Ø×¢</a>
  File "c:\users\16496\appdata\local\programs\python\python37-32\lib\site-packages\flask\helpers.py", line 338, in url_for
    return appctx.app.handle_url_build_error(error, endpoint, values)
  File "c:\users\16496\appdata\local\programs\python\python37-32\lib\site-packages\flask\helpers.py", line 326, in url_for
    endpoint, values, method=method, force_external=external
  File "c:\users\16496\appdata\local\programs\python\python37-32\lib\site-packages\werkzeug\routing.py", line 2315, in build
    raise BuildError(endpoint, values, method, self)
werkzeug.routing.BuildError: Could not build url for endpoint 'follow' with values ['username']. Did you mean 'login' instead?
2022-03-12 23:13:11,470 ERROR: Exception on /user/xiang [GET] [in c:\users\16496\appdata\local\programs\python\python37-32\lib\site-packages\flask\app.py:1458]
Traceback (most recent call last):
  File "c:\users\16496\appdata\local\programs\python\python37-32\lib\site-packages\flask\app.py", line 2073, in wsgi_app
    response = self.full_dispatch_request()
  File "c:\users\16496\appdata\local\programs\python\python37-32\lib\site-packages\flask\app.py", line 1518, in full_dispatch_request
    rv = self.handle_user_exception(e)
  File "c:\users\16496\appdata\local\programs\python\python37-32\lib\site-packages\flask\app.py", line 1516, in full_dispatch_request
    rv = self.dispatch_request()
  File "c:\users\16496\appdata\local\programs\python\python37-32\lib\site-packages\flask\app.py", line 1502, in dispatch_request
    return self.ensure_sync(self.view_functions[rule.endpoint])(**req.view_args)
  File "c:\users\16496\appdata\local\programs\python\python37-32\lib\site-packages\flask_login\utils.py", line 272, in decorated_view
    return func(*args, **kwargs)
  File "D:\python\microblog\app\routes.py", line 122, in user
    return render_template('user.html', user=user, posts=posts.items, next_url=next_url, prev_url=prev_url)
  File "c:\users\16496\appdata\local\programs\python\python37-32\lib\site-packages\flask\templating.py", line 150, in render_template
    ctx.app,
  File "c:\users\16496\appdata\local\programs\python\python37-32\lib\site-packages\flask\templating.py", line 128, in _render
    rv = template.render(context)
  File "c:\users\16496\appdata\local\programs\python\python37-32\lib\site-packages\jinja2\environment.py", line 1291, in render
    self.environment.handle_exception()
  File "c:\users\16496\appdata\local\programs\python\python37-32\lib\site-packages\jinja2\environment.py", line 925, in handle_exception
    raise rewrite_traceback_stack(source=source)
  File "D:\python\microblog\app\templates\user.html", line 1, in top-level template code
    {% extends "base.html" %}
  File "D:\python\microblog\app\templates\base.html", line 35, in top-level template code
    {% block content %}
  File "D:\python\microblog\app\templates\user.html", line 24, in block 'content'
    <a href="{{ url_for('follow', username=user.username) }}">¹Ø×¢</a>
  File "c:\users\16496\appdata\local\programs\python\python37-32\lib\site-packages\flask\helpers.py", line 338, in url_for
    return appctx.app.handle_url_build_error(error, endpoint, values)
  File "c:\users\16496\appdata\local\programs\python\python37-32\lib\site-packages\flask\helpers.py", line 326, in url_for
    endpoint, values, method=method, force_external=external
  File "c:\users\16496\appdata\local\programs\python\python37-32\lib\site-packages\werkzeug\routing.py", line 2315, in build
    raise BuildError(endpoint, values, method, self)
werkzeug.routing.BuildError: Could not build url for endpoint 'follow' with values ['username']. Did you mean 'login' instead?
2022-03-13 13:36:46,390 INFO: Microblog startup [in D:\python\microblog\app\__init__.py:44]
2022-03-13 13:45:31,303 INFO: Microblog startup [in D:\python\microblog\app\__init__.py:48]
2022-03-13 13:46:48,351 INFO: Microblog startup [in D:\python\microblog\app\__init__.py:48]
2022-03-13 14:37:29,340 INFO: Microblog startup [in D:\python\microblog\app\__init__.py:48]
2022-03-13 14:37:58,292 ERROR: Exception on /reset_password_request [GET] [in c:\users\16496\appdata\local\programs\python\python37-32\lib\site-packages\flask\app.py:1458]
Traceback (most recent call last):
  File "c:\users\16496\appdata\local\programs\python\python37-32\lib\site-packages\flask\app.py", line 2073, in wsgi_app
    response = self.full_dispatch_request()
  File "c:\users\16496\appdata\local\programs\python\python37-32\lib\site-packages\flask\app.py", line 1518, in full_dispatch_request
    rv = self.handle_user_exception(e)
  File "c:\users\16496\appdata\local\programs\python\python37-32\lib\site-packages\flask\app.py", line 1516, in full_dispatch_request
    rv = self.dispatch_request()
  File "c:\users\16496\appdata\local\programs\python\python37-32\lib\site-packages\flask\app.py", line 1502, in dispatch_request
    return self.ensure_sync(self.view_functions[rule.endpoint])(**req.view_args)
  File "D:\python\microblog\app\routes.py", line 128, in reset_password_request
    return render_template('reset_password_request.html', title='Reset Password', form=form)
  File "c:\users\16496\appdata\local\programs\python\python37-32\lib\site-packages\flask\templating.py", line 148, in render_template
    ctx.app.jinja_env.get_or_select_template(template_name_or_list),
  File "c:\users\16496\appdata\local\programs\python\python37-32\lib\site-packages\jinja2\environment.py", line 1068, in get_or_select_template
    return self.get_template(template_name_or_list, parent, globals)
  File "c:\users\16496\appdata\local\programs\python\python37-32\lib\site-packages\jinja2\environment.py", line 997, in get_template
    return self._load_template(name, globals)
  File "c:\users\16496\appdata\local\programs\python\python37-32\lib\site-packages\jinja2\environment.py", line 958, in _load_template
    template = self.loader.load(self, name, self.make_globals(globals))
  File "c:\users\16496\appdata\local\programs\python\python37-32\lib\site-packages\jinja2\loaders.py", line 137, in load
    code = environment.compile(source, name, filename)
  File "c:\users\16496\appdata\local\programs\python\python37-32\lib\site-packages\jinja2\environment.py", line 757, in compile
    self.handle_exception(source=source_hint)
  File "c:\users\16496\appdata\local\programs\python\python37-32\lib\site-packages\jinja2\environment.py", line 925, in handle_exception
    raise rewrite_traceback_stack(source=source)
  File "D:\python\microblog\app\templates\reset_password_request.html", line 12, in template
    {{% endfor %}}
jinja2.exceptions.TemplateSyntaxError: unexpected '%'
